<?xml version="1.0" encoding="utf-8"?>
<!-- This URDF was automatically created by SolidWorks to URDF Exporter! Originally created by Stephen Brawner (brawner@gmail.com) 
     Commit Version: 1.6.0-4-g7f85cfe  Build Version: 1.6.7995.38578
     For more information, please see http://wiki.ros.org/sw_urdf_exporter -->
<robot
  name="toycar">
  <link
    name="chasis">
    <inertial>
      <origin
        xyz="0.024975925947581 -4.20756987495885E-06 0.11864503176387"
        rpy="0 0 0" />
      <mass
        value="54.8750756000207" />
      <inertia
        ixx="2.42445741544445"
        ixy="1.57861384663051E-06"
        ixz="-0.0584114974888804"
        iyy="4.58034547568856"
        iyz="1.70792236750801E-05"
        izz="5.45749697284106" />
    </inertial>
    <visual>
      <origin
        xyz="0 0 0"
        rpy="0 0 0" />
      <geometry>
        <mesh
          filename="package://toycar/meshes/chasis.STL" />
      </geometry>
      <material
        name="">
        <color
          rgba="1 1 1 1" />
      </material>
    </visual>
    <collision>
      <origin
        xyz="0 0 0"
        rpy="0 0 0" />
      <geometry>
        <mesh
          filename="package://toycar/meshes/chasis.STL" />
      </geometry>
    </collision>
  </link>
  <link
    name="Lsteer_link">
    <inertial>
      <origin
        xyz="0 -0.0168352126518257 -0.0927078194170612"
        rpy="0 0 0" />
      <mass
        value="0.57494461281035" />
      <inertia
        ixx="0.00250810030198503"
        ixy="3.18549876034167E-19"
        ixz="-2.96437285772016E-19"
        iyy="0.00241403437982035"
        iyz="-0.000119539993842074"
        izz="0.00100659805855099" />
    </inertial>
    <visual>
      <origin
        xyz="0 0 0"
        rpy="0 0 0" />
      <geometry>
        <mesh
          filename="package://toycar/meshes/Lsteer_link.STL" />
      </geometry>
      <material
        name="">
        <color
          rgba="1 1 1 1" />
      </material>
    </visual>
    <collision>
      <origin
        xyz="0 0 0"
        rpy="0 0 0" />
      <geometry>
        <mesh
          filename="package://toycar/meshes/Lsteer_link.STL" />
      </geometry>
    </collision>
  </link>
  <joint
    name="Lsteer_joint"
    type="revolute">
    <origin
      xyz="0.4075 0.27965 0.1778"
      rpy="0 0 0" />
    <parent
      link="chasis" />
    <child
      link="Lsteer_link" />
    <axis
      xyz="0 0 1" />
    <limit
      lower="-1.047"
      upper="1.047"
      effort="50"
      velocity="10" />
    <dynamics
      damping="0.1"
      friction="0.1" />
  </joint>
  <link
    name="LFWcar_link">
    <inertial>
      <origin
        xyz="-1.11022302462516E-16 0.00495299999999999 2.77555756156289E-17"
        rpy="0 0 0" />
      <mass
        value="1.0295734289742" />
      <inertia
        ixx="0.00366190604021718"
        ixy="-7.253056459933E-19"
        ixz="-1.68917639682057E-20"
        iyy="0.00686775736288754"
        iyz="1.160228447991E-20"
        izz="0.00366190604021718" />
    </inertial>
    <visual>
      <origin
        xyz="0 0 0"
        rpy="0 0 0" />
      <geometry>
        <mesh
          filename="package://toycar/meshes/LFWcar_link.STL" />
      </geometry>
      <material
        name="">
        <color
          rgba="1 1 1 1" />
      </material>
    </visual>
    <collision>
      <origin
        xyz="0 0 0"
        rpy="0 0 0" />
      <geometry>
        <mesh
          filename="package://toycar/meshes/LFWcar_link.STL" />
      </geometry>
    </collision>
  </link>
  <joint
    name="LFWcar_joint"
    type="continuous">
    <origin
      xyz="0 0.004953 -0.1397"
      rpy="0 0 0" />
    <parent
      link="Lsteer_link" />
    <child
      link="LFWcar_link" />
    <axis
      xyz="0 1 0" />
    <dynamics
      damping="0.1"
      friction="0.1" />
  </joint>
  <link
    name="Rsteer_link">
    <inertial>
      <origin
        xyz="0 0.0168352126518256 -0.0927078194170612"
        rpy="0 0 0" />
      <mass
        value="0.574944612810349" />
      <inertia
        ixx="0.00250810030198503"
        ixy="4.16599401067996E-19"
        ixz="-1.83535018889357E-19"
        iyy="0.00241403437982035"
        iyz="0.000119539993842074"
        izz="0.00100659805855099" />
    </inertial>
    <visual>
      <origin
        xyz="0 0 0"
        rpy="0 0 0" />
      <geometry>
        <mesh
          filename="package://toycar/meshes/Rsteer_link.STL" />
      </geometry>
      <material
        name="">
        <color
          rgba="1 1 1 1" />
      </material>
    </visual>
    <collision>
      <origin
        xyz="0 0 0"
        rpy="0 0 0" />
      <geometry>
        <mesh
          filename="package://toycar/meshes/Rsteer_link.STL" />
      </geometry>
    </collision>
  </link>
  <joint
    name="Rsteer_joint"
    type="revolute">
    <origin
      xyz="0.4075 -0.27965 0.1778"
      rpy="0 0 0" />
    <parent
      link="chasis" />
    <child
      link="Rsteer_link" />
    <axis
      xyz="0 0 1" />
    <limit
      lower="-1.047"
      upper="1.047"
      effort="50"
      velocity="10" />
    <dynamics
      damping="0.1"
      friction="0.1" />
  </joint>
  <link
    name="RFWcar_link">
    <inertial>
      <origin
        xyz="-1.11022302462516E-16 -0.00495299999999971 1.11022302462516E-16"
        rpy="0 0 0" />
      <mass
        value="1.0295734289742" />
      <inertia
        ixx="0.00366190604021718"
        ixy="7.17741166935487E-20"
        ixz="-3.22616672282114E-19"
        iyy="0.00686775736288754"
        iyz="-2.28032724591382E-18"
        izz="0.00366190604021718" />
    </inertial>
    <visual>
      <origin
        xyz="0 0 0"
        rpy="0 0 0" />
      <geometry>
        <mesh
          filename="package://toycar/meshes/RFWcar_link.STL" />
      </geometry>
      <material
        name="">
        <color
          rgba="1 1 1 1" />
      </material>
    </visual>
    <collision>
      <origin
        xyz="0 0 0"
        rpy="0 0 0" />
      <geometry>
        <mesh
          filename="package://toycar/meshes/RFWcar_link.STL" />
      </geometry>
    </collision>
  </link>
  <joint
    name="RFWcar_joint"
    type="continuous">
    <origin
      xyz="0 -0.004953 -0.1397"
      rpy="0 0 0" />
    <parent
      link="Rsteer_link" />
    <child
      link="RFWcar_link" />
    <axis
      xyz="0 1 0" />
    <dynamics
      damping="0.1"
      friction="0.1" />
  </joint>
  <link
    name="RWcar_link">
    <inertial>
      <origin
        xyz="-1.38777878078145E-17 -2.77555756156289E-17 -2.77555756156289E-17"
        rpy="0 0 0" />
      <mass
        value="3.14329408449046" />
      <inertia
        ixx="0.155511981185489"
        ixy="-9.56720556115731E-18"
        ixz="3.05488395539211E-19"
        iyy="0.0115881792673136"
        iyz="1.07499422845588E-18"
        izz="0.155511981185489" />
    </inertial>
    <visual>
      <origin
        xyz="0 0 0"
        rpy="0 0 0" />
      <geometry>
        <mesh
          filename="package://toycar/meshes/RWcar_link.STL" />
      </geometry>
      <material
        name="">
        <color
          rgba="1 1 1 1" />
      </material>
    </visual>
    <collision>
      <origin
        xyz="0 0 0"
        rpy="0 0 0" />
      <geometry>
        <mesh
          filename="package://toycar/meshes/RWcar_link.STL" />
      </geometry>
    </collision>
  </link>
  <joint
    name="RWcar_joint"
    type="continuous">
    <origin
      xyz="-0.3327 0.00254 0.0381"
      rpy="0 0 0" />
    <parent
      link="chasis" />
    <child
      link="RWcar_link" />
    <axis
      xyz="0 -1 0" />
    <limit
      lower="0"
      upper="0"
      effort="1000"
      velocity="10" />
    <dynamics
      damping="0.1"
      friction="0.1" />
  </joint>
  <link
    name="hinge_link">
    <inertial>
      <origin
        xyz="-0.78132389558606 1.85962356624714E-15 0.129752242427174"
        rpy="0 0 0" />
      <mass
        value="54.7539865578095" />
      <inertia
        ixx="3.66810627316164"
        ixy="2.24810919232119E-15"
        ixz="-0.152403907922576"
        iyy="7.72211205786556"
        iyz="-5.42414946047012E-16"
        izz="9.22784316705244" />
    </inertial>
    <visual>
      <origin
        xyz="0 0 0"
        rpy="0 0 0" />
      <geometry>
        <mesh
          filename="package://toycar/meshes/hinge_link.STL" />
      </geometry>
      <material
        name="">
        <color
          rgba="1 1 1 1" />
      </material>
    </visual>
    <collision>
      <origin
        xyz="0 0 0"
        rpy="0 0 0" />
      <geometry>
        <mesh
          filename="package://toycar/meshes/hinge_link.STL" />
      </geometry>
    </collision>
  </link>
  <joint
    name="hinge_joint"
    type="revolute">
    <origin
      xyz="-0.557 0 0.0381"
      rpy="0 0 0" />
    <parent
      link="chasis" />
    <child
      link="hinge_link" />
    <axis
      xyz="0 0 -1" />
    <limit
      lower="-1.047"
      upper="1.047"
      effort="0"
      velocity="0" />
    <dynamics
      damping="0.1"
      friction="0.1" />
  </joint>
  <link
    name="FWtrolley_link">
    <inertial>
      <origin
        xyz="0 5.55111512312578E-17 -2.77555756156289E-17"
        rpy="0 0 0" />
      <mass
        value="3.14329408449046" />
      <inertia
        ixx="0.155511981185489"
        ixy="-2.52603298389416E-17"
        ixz="1.70420269777737E-19"
        iyy="0.0115881792673136"
        iyz="6.88865295905193E-19"
        izz="0.155511981185489" />
    </inertial>
    <visual>
      <origin
        xyz="0 0 0"
        rpy="0 0 0" />
      <geometry>
        <mesh
          filename="package://toycar/meshes/FWtrolley_link.STL" />
      </geometry>
      <material
        name="">
        <color
          rgba="1 1 1 1" />
      </material>
    </visual>
    <collision>
      <origin
        xyz="0 0 0"
        rpy="0 0 0" />
      <geometry>
        <mesh
          filename="package://toycar/meshes/FWtrolley_link.STL" />
      </geometry>
    </collision>
  </link>
  <joint
    name="FWtrolley_joint"
    type="continuous">
    <origin
      xyz="-0.592340905122494 0.00253999999999979 0"
      rpy="0 0 0" />
    <parent
      link="hinge_link" />
    <child
      link="FWtrolley_link" />
    <axis
      xyz="0 -1 0" />
    <dynamics
      damping="0.1"
      friction="0.1" />
  </joint>
  <link
    name="RWtrolley_link">
    <inertial>
      <origin
        xyz="0 2.77555756156289E-16 0"
        rpy="0 0 0" />
      <mass
        value="3.14329408449046" />
      <inertia
        ixx="0.155511981185489"
        ixy="-2.7389670791255E-18"
        ixz="1.06777441062471E-17"
        iyy="0.0115881792673136"
        iyz="3.93709043435314E-17"
        izz="0.155511981185489" />
    </inertial>
    <visual>
      <origin
        xyz="0 0 0"
        rpy="0 0 0" />
      <geometry>
        <mesh
          filename="package://toycar/meshes/RWtrolley_link.STL" />
      </geometry>
      <material
        name="">
        <color
          rgba="1 1 1 1" />
      </material>
    </visual>
    <collision>
      <origin
        xyz="0 0 0"
        rpy="0 0 0" />
      <geometry>
        <mesh
          filename="package://toycar/meshes/RWtrolley_link.STL" />
      </geometry>
    </collision>
  </link>
  <joint
    name="RWtrolley_joint"
    type="continuous">
    <origin
      xyz="-1.04954090512249 0.00253999999999993 0"
      rpy="0 0 0" />
    <parent
      link="hinge_link" />
    <child
      link="RWtrolley_link" />
    <axis
      xyz="0 -1 0" />
    <dynamics
      damping="0.1"
      friction="0.1" />
  </joint>
  <link
    name="Lidar_link">
    <inertial>
      <origin
        xyz="-0.0502486950872626 5.55111512312578E-17 0.499119713696591"
        rpy="0 0 0" />
      <mass
        value="0.590091649457795" />
      <inertia
        ixx="0.000624272686333271"
        ixy="-1.54300286232164E-22"
        ixz="-4.36032848945782E-20"
        iyy="0.000624272686333271"
        iyz="-4.66419977999995E-21"
        izz="0.000728905599655388" />
    </inertial>
    <visual>
      <origin
        xyz="0 0 0"
        rpy="0 0 0" />
      <geometry>
        <mesh
          filename="package://toycar/meshes/Lidar_link.STL" />
      </geometry>
      <material
        name="">
        <color
          rgba="1 1 1 1" />
      </material>
    </visual>
    <collision>
      <origin
        xyz="0 0 0"
        rpy="0 0 0" />
      <geometry>
        <mesh
          filename="package://toycar/meshes/Lidar_link.STL" />
      </geometry>
    </collision>
  </link>
  <joint
    name="Lidar_joint"
    type="fixed">
    <origin
      xyz="0 0 0"
      rpy="0 0 0" />
    <parent
      link="chasis" />
    <child
      link="Lidar_link" />
    <axis
      xyz="0 0 0" />
  </joint>
</robot>